Workbook

Sheet Candidate Test
A1: MIS Executive – Excel & Analytical Skills Assessment
A3: Purpose | B3: Tests practical Excel ability and analytical thinking for an MIS Executive role.
A4: Suggested time | B4: 75–90 minutes
A5: Total marks | B5: 100
A6: Important | B6: Do not edit the raw data sheets. Complete answers/formulas in the spaces provided.
A7: Candidate Name
A10: SECTION A | B10: Excel Fundamentals
A11: SECTION B | B11: Data Cleaning & Lookups
A12: SECTION C | B12: Reporting & Pivot Analysis
A13: SECTION D | B13: Business Analysis
A14: SECTION E | B14: MIS Judgment / Practical Situations
A17: ID | B17: Question
A18: A1 | B18: In Transaction Data, calculate the Total Business Amount using Amount × 1 for successful transactions only. Use the Status field to exclude Failed transactions. | C18: =SUMIFS('Transaction Data'!E:E,'Transaction Data'!F:F,"Success") -> 2691750
A19: A2 | B19: Calculate the average successful transaction amount. | C19: =AVERAGEIFS('Transaction Data'!E:E,'Transaction Data'!F:F,"Success") -> 5955.1991
A20: A3 | B20: Find the number of unique agents who had at least one successful transaction.
A21: A4 | B21: Using a formula, return the month name from Transaction Date in a new column. | C21: text()
A22: A5 | B22: Apply conditional formatting to highlight transactions above ₹10,000.
A23: B1 | B23: Using Agent Master, bring Agent Name and ASM into Transaction Data using Agent ID. Use a lookup formula.
A24: B2 | B24: Using Product Mapping, convert Product Code into Product Name.
A25: B3 | B25: Identify and count transactions where Agent ID is missing from Agent Master.
A26: B4 | B26: Create a clean Month column in the format YYYY-MM and use it consistently for reporting.
A27: B5 | B27: Explain in one sentence when you would use XLOOKUP instead of VLOOKUP. | C27: because vlookup search result from his right side only and xlookup search result both side
A28: C1 | B28: Create a PivotTable showing Business Amount by Product.
A29: C2 | B29: Create a PivotTable showing Business Amount by ASM.
A30: C3 | B30: Create a month-wise Product-wise Business Amount report.
A31: C4 | B31: Add transaction count and average transaction value to the Product report.
A32: C5 | B32: Create a chart showing monthly Business Amount trend.
A33: D1 | B33: Which product has the highest Business Amount? State the amount and percentage contribution to total.
A34: D2 | B34: Which ASM has the lowest Business Amount among ASMs with at least 20 successful transactions? State the logic used.
A35: D3 | B35: Identify the product with the biggest month-on-month decline in Business Amount. Show the calculation.

Sheet Sheet1
A1: Status | B1: Success
A3: Row Labels | B3: Sum of Amount
A4: AEPS | B4: 341750
A5: APAY | B5: 494000
A6: BBPS | B6: 378500
A7: DMT | B7: 384000
A8: MATM | B8: 665250
A9: UPI | B9: 428250
A10: Grand Total | B10: 2691750

Sheet Sheet2
A1: Status | B1: Success
A3: Row Labels | B3: Sum of Amount
A4: August | B4: 1355750
A5: AEPS | B5: 197000
A6: APAY | B6: 176750
A7: BBPS | B7: 249500
A8: DMT | B8: 220750
A9: MATM | B9: 324500
A10: UPI | B10: 187250
A11: September | B11: 1336000
A12: AEPS | B12: 144750
A13: APAY | B13: 317250
A14: BBPS | B14: 129000
A15: DMT | B15: 163250
... A18: Grand Total | B18: 2691750

Sheet Transaction Data
A1: Txn ID | B1: Transaction Date | C1: Agent ID | D1: Product Code | E1: Amount | F1: Status | G1: Transaction Type | H1: Region | I1: Month | J1: Agent Name | K1: ASM | L1: Month_Name | M1: Product_Name | N1: year_Mpnth | O1: Agent Name
A2: T0001 | B2: 46275 | C2: A108 | D2: P01 | E2: 15000 | F2: Success | G2: Retailer | H2: West | I2: =TEXT(B2,"yyyy-mm") -> 2026-09 | K2: =IFERROR(_xludf.XLOOKUP(C2,'Agent Master'!$A:$A,'Agent Master'!$C:$C,"Missing"),"Missing") -> Missing | L2: =TEXT(B2,"mmmm") -> September | M2: =_xlfn.XLOOKUP('Transaction Data'!D2,ProductMap[Product Code],ProductMap[Product Name]) -> AEPS | N2: =TEXT(B2,"yyyy-mm") -> 2026-09 | O2: {=IFERROR(_xlfn.XLOOKUP(C2,AgentMaster[[#All],[Agent ID]],AgentMaster[[#All],[Agent Name]]),"")} -> Agent 108 | P2: =COUNTIFS(O:O,O2,F:F,"Success") -> 12
A3: T0002 | B3: 46243 | C3: A107 | D3: P06 | E3: 15000 | F3: Success | G3: Retailer | H3: East | I3: =TEXT(B3,"yyyy-mm") -> 2026-08 | J3: =IFERROR(_xludf.XLOOKUP(C3,'Agent Master'!$A:$A,'Agent Master'!$B:$B,"Missing"),"Missing") -> Missing | K3: =IFERROR(_xludf.XLOOKUP(C3,'Agent Master'!$A:$A,'Agent Master'!$C:$C,"Missing"),"Missing") -> Missing | L3: =TEXT(B3,"mmmm") -> August | M3: =_xlfn.XLOOKUP('Transaction Data'!D3,ProductMap[Product Code],ProductMap[Product Name]) -> MATM | N3: =TEXT(B3,"yyyy-mm") -> 2026-08 | O3: {=IFERROR(_xlfn.XLOOKUP(C3,AgentMaster[[#All],[Agent ID]],AgentMaster[[#All],[Agent Name]]),"")} -> Agent 107 | P3: =COUNTIFS(O:O,O3,F:F,"Success") -> 16
A4: T0003 | B4: 46237 | C4: A102 | D4: P01 | E4: 1000 | F4: Success | G4: Retailer | H4: North | I4: =TEXT(B4,"yyyy-mm") -> 2026-08 | J4: =IFERROR(_xludf.XLOOKUP(C4,'Agent Master'!$A:$A,'Agent Master'!$B:$B,"Missing"),"Missing") -> Missing | K4: =IFERROR(_xludf.XLOOKUP(C4,'Agent Master'!$A:$A,'Agent Master'!$C:$C,"Missing"),"Missing") -> Missing | L4: =TEXT(B4,"mmmm") -> August | M4: =_xlfn.XLOOKUP('Transaction Data'!D4,ProductMap[Product Code],ProductMap[Product Name]) -> AEPS | N4: =TEXT(B4,"yyyy-mm") -> 2026-08 | O4: {=IFERROR(_xlfn.XLOOKUP(C4,AgentMaster[[#All],[Agent ID]],AgentMaster[[#All],[Agent Name]]),"")} -> Agent 102 | P4: =COUNTIFS(O:O,O4,F:F,"Success") -> 13 | Q4: {=_xlfn.UNIQUE(C:C)} -> Agent ID
A5: T0004 | B5: 46270 | C5: A113 | D5: P06 | E5: 12500 | F5: Success | G5: Distributor | H5: West | I5: =TEXT(B5,"yyyy-mm") -> 2026-09 | J5: =IFERROR(_xludf.XLOOKUP(C5,'Agent Master'!$A:$A,'Agent Master'!$B:$B,"Missing"),"Missing") -> Missing | K5: =IFERROR(_xludf.XLOOKUP(C5,'Agent Master'!$A:$A,'Agent Master'!$C:$C,"Missing"),"Missing") -> Missing | L5: =TEXT(B5,"mmmm") -> September | M5: =_xlfn.XLOOKUP('Transaction Data'!D5,ProductMap[Product Code],ProductMap[Product Name]) -> MATM | N5: =TEXT(B5,"yyyy-mm") -> 2026-09 | O5: {=IFERROR(_xlfn.XLOOKUP(C5,AgentMaster[[#All],[Agent ID]],AgentMaster[[#All],[Agent Name]]),"")} -> Agent 113 | P5: =COUNTIFS(O:O,O5,F:F,"Success") -> 12 | Q5: A108 | R5: =IF(COUNTIFS(C:C,Q5,F:F,"Success")>0,1,0) -> 1
A6: T0005 | B6: 46263 | C6: A138 | D6: P03 | E6: 20000 | F6: Success | G6: Retailer | H6: East | I6: =TEXT(B6,"yyyy-mm") -> 2026-08 | J6: =IFERROR(_xludf.XLOOKUP(C6,'Agent Master'!$A:$A,'Agent Master'!$B:$B,"Missing"),"Missing") -> Missing | K6: =IFERROR(_xludf.XLOOKUP(C6,'Agent Master'!$A:$A,'Agent Master'!$C:$C,"Missing"),"Missing") -> Missing | L6: =TEXT(B6,"mmmm") -> August | M6: =_xlfn.XLOOKUP('Transaction Data'!D6,ProductMap[Product Code],ProductMap[Product Name]) -> APAY | N6: =TEXT(B6,"yyyy-mm") -> 2026-08 | O6: {=IFERROR(_xlfn.XLOOKUP(C6,AgentMaster[[#All],[Agent ID]],AgentMaster[[#All],[Agent Name]]),"")} -> Agent 138 | P6: =COUNTIFS(O:O,O6,F:F,"Success") -> 4 | Q6: A107 | R6: =IF(COUNTIFS(C:C,Q6,F:F,"Success")>0,1,0) -> 1
A7: T0006 | B7: 46256 | C7: A118 | D7: P02 | E7: 1000 | F7: Success | G7: Retailer | H7: North | I7: =TEXT(B7,"yyyy-mm") -> 2026-08 | J7: =IFERROR(_xludf.XLOOKUP(C7,'Agent Master'!$A:$A,'Agent Master'!$B:$B,"Missing"),"Missing") -> Missing | K7: =IFERROR(_xludf.XLOOKUP(C7,'Agent Master'!$A:$A,'Agent Master'!$C:$C,"Missing"),"Missing") -> Missing | L7: =TEXT(B7,"mmmm") -> August | M7: =_xlfn.XLOOKUP('Transaction Data'!D7,ProductMap[Product Code],ProductMap[Product Name]) -> UPI | N7: =TEXT(B7,"yyyy-mm") -> 2026-08 | O7: {=IFERROR(_xlfn.XLOOKUP(C7,AgentMaster[[#All],[Agent ID]],AgentMaster[[#All],[Agent Name]]),"")} -> Agent 118 | P7: =COUNTIFS(O:O,O7,F:F,"Success") -> 11 | Q7: A102 | R7: =IF(COUNTIFS(C:C,Q7,F:F,"Success")>0,1,0) -> 1
A8: T0007 | B8: 46259 | C8: A107 | D8: P03 | E8: 2000 | F8: Failed | G8: Distributor | H8: North | I8: =TEXT(B8,"yyyy-mm") -> 2026-08 | J8: =IFERROR(_xludf.XLOOKUP(C8,'Agent Master'!$A:$A,'Agent Master'!$B:$B,"Missing"),"Missing") -> Missing | K8: =IFERROR(_xludf.XLOOKUP(C8,'Agent Master'!$A:$A,'Agent Master'!$C:$C,"Missing"),"Missing") -> Missing | L8: =TEXT(B8,"mmmm") -> August | M8: =_xlfn.XLOOKUP('Transaction Data'!D8,ProductMap[Product Code],ProductMap[Product Name]) -> APAY | N8: =TEXT(B8,"yyyy-mm") -> 2026-08 | O8: {=IFERROR(_xlfn.XLOOKUP(C8,AgentMaster[[#All],[Agent ID]],AgentMaster[[#All],[Agent Name]]),"")} -> Agent 107 | P8: =COUNTIFS(O:O,O8,F:F,"Success") -> 16 | Q8: A113 | R8: =IF(COUNTIFS(C:C,Q8,F:F,"Success")>0,1,0) -> 1
A9: T0008 | B9: 46281 | C9: A130 | D9: P05 | E9: 500 | F9: Success | G9: Retailer | H9: South | I9: =TEXT(B9,"yyyy-mm") -> 2026-09 | J9: =IFERROR(_xludf.XLOOKUP(C9,'Agent Master'!$A:$A,'Agent Master'!$B:$B,"Missing"),"Missing") -> Missing | K9: =IFERROR(_xludf.XLOOKUP(C9,'Agent Master'!$A:$A,'Agent Master'!$C:$C,"Missing"),"Missing") -> Missing | L9: =TEXT(B9,"mmmm") -> September | M9: =_xlfn.XLOOKUP('Transaction Data'!D9,ProductMap[Product Code],ProductMap[Product Name]) -> BBPS | N9: =TEXT(B9,"yyyy-mm") -> 2026-09 | O9: {=IFERROR(_xlfn.XLOOKUP(C9,AgentMaster[[#All],[Agent ID]],AgentMaster[[#All],[Agent Name]]),"")} -> Agent 130 | P9: =COUNTIFS(O:O,O9,F:F,"Success") -> 16 | Q9: A138 | R9: =IF(COUNTIFS(C:C,Q9,F:F,"Success")>0,1,0) -> 1
A10: T0009 | B10: 46288 | C10: A999 | D10: P05 | E10: 2000 | F10: Failed | G10: Retailer | H10: North | I10: =TEXT(B10,"yyyy-mm") -> 2026-09 | J10: =IFERROR(_xludf.XLOOKUP(C10,'Agent Master'!$A:$A,'Agent Master'!$B:$B,"Missing"),"Missing") -> Missing | K10: =IFERROR(_xludf.XLOOKUP(C10,'Agent Master'!$A:$A,'Agent Master'!$C:$C,"Missing"),"Missing") -> Missing | L10: =TEXT(B10,"mmmm") -> September | M10: =_xlfn.XLOOKUP('Transaction Data'!D10,ProductMap[Product Code],ProductMap[Product Name]) -> BBPS | N10: =TEXT(B10,"yyyy-mm") -> 2026-09 | O10: {=IFERROR(_xlfn.XLOOKUP(C10,AgentMaster[[#All],[Agent ID]],AgentMaster[[#All],[Agent Name]]),"")} | P10: =COUNTIFS(O:O,O10,F:F,"Success") -> 25 | Q10: A118 | R10: =IF(COUNTIFS(C:C,Q10,F:F,"Success")>0,1,0) -> 1
A11: T0010 | B11: 46237 | C11: A115 | D11: P03 | E11: 500 | F11: Success | G11: Retailer | H11: East | I11: =TEXT(B11,"yyyy-mm") -> 2026-08 | J11: =IFERROR(_xludf.XLOOKUP(C11,'Agent Master'!$A:$A,'Agent Master'!$B:$B,"Missing"),"Missing") -> Missing | K11: =IFERROR(_xludf.XLOOKUP(C11,'Agent Master'!$A:$A,'Agent Master'!$C:$C,"Missing"),"Missing") -> Missing | L11: =TEXT(B11,"mmmm") -> August | M11: =_xlfn.XLOOKUP('Transaction Data'!D11,ProductMap[Product Code],ProductMap[Product Name]) -> APAY | N11: =TEXT(B11,"yyyy-mm") -> 2026-08 | O11: {=IFERROR(_xlfn.XLOOKUP(C11,AgentMaster[[#All],[Agent ID]],AgentMaster[[#All],[Agent Name]]),"")} -> Agent 115 | P11: =COUNTIFS(O:O,O11,F:F,"Success") -> 11 | Q11: A130 | R11: =IF(COUNTIFS(C:C,Q11,F:F,"Success")>0,1,0) -> 1
A12: T0011 | B12: 46252 | C12: A130 | D12: P06 | E12: 2000 | F12: Success | G12: Distributor | H12: South | I12: =TEXT(B12,"yyyy-mm") -> 2026-08 | J12: =IFERROR(_xludf.XLOOKUP(C12,'Agent Master'!$A:$A,'Agent Master'!$B:$B,"Missing"),"Missing") -> Missing | K12: =IFERROR(_xludf.XLOOKUP(C12,'Agent Master'!$A:$A,'Agent Master'!$C:$C,"Missing"),"Missing") -> Missing | L12: =TEXT(B12,"mmmm") -> August | M12: =_xlfn.XLOOKUP('Transaction Data'!D12,ProductMap[Product Code],ProductMap[Product Name]) -> MATM | N12: =TEXT(B12,"yyyy-mm") -> 2026-08 | O12: {=IFERROR(_xlfn.XLOOKUP(C12,AgentMaster[[#All],[Agent ID]],AgentMaster[[#All],[Agent Name]]),"")} -> Agent 130 | P12: =COUNTIFS(O:O,O12,F:F,"Success") -> 16 | Q12: A999 | R12: =IF(COUNTIFS(C:C,Q12,F:F,"Success")>0,1,0) -> 1
A13: T0012 | B13: 46248 | C13: A118 | D13: P06 | E13: 12500 | F13: Success | G13: Retailer | H13: West | I13: =TEXT(B13,"yyyy-mm") -> 2026-08 | J13: =IFERROR(_xludf.XLOOKUP(C13,'Agent Master'!$A:$A,'Agent Master'!$B:$B,"Missing"),"Missing") -> Missing | K13: =IFERROR(_xludf.XLOOKUP(C13,'Agent Master'!$A:$A,'Agent Master'!$C:$C,"Missing"),"Missing") -> Missing | L13: =TEXT(B13,"mmmm") -> August | M13: =_xlfn.XLOOKUP('Transaction Data'!D13,ProductMap[Product Code],ProductMap[Product Name]) -> MATM | N13: =TEXT(B13,"yyyy-mm") -> 2026-08 | O13: {=IFERROR(_xlfn.XLOOKUP(C13,AgentMaster[[#All],[Agent ID]],AgentMaster[[#All],[Agent Name]]),"")} -> Agent 118 | P13: =COUNTIFS(O:O,O13,F:F,"Success") -> 11 | Q13: A115 | R13: =IF(COUNTIFS(C:C,Q13,F:F,"Success")>0,1,0) -> 1
A14: T0013 | B14: 46269 | C14: A116 | D14: P02 | E14: 5000 | F14: Success | G14: Distributor | H14: West | I14: =TEXT(B14,"yyyy-mm") -> 2026-09 | J14: =IFERROR(_xludf.XLOOKUP(C14,'Agent Master'!$A:$A,'Agent Master'!$B:$B,"Missing"),"Missing") -> Missing | K14: =IFERROR(_xludf.XLOOKUP(C14,'Agent Master'!$A:$A,'Agent Master'!$C:$C,"Missing"),"Missing") -> Missing | L14: =TEXT(B14,"mmmm") -> September | M14: =_xlfn.XLOOKUP('Transaction Data'!D14,ProductMap[Product Code],ProductMap[Product Name]) -> UPI | N14: =TEXT(B14,"yyyy-mm") -> 2026-09 | O14: {=IFERROR(_xlfn.XLOOKUP(C14,AgentMaster[[#All],[Agent ID]],AgentMaster[[#All],[Agent Name]]),"")} -> Agent 116 | P14: =COUNTIFS(O:O,O14,F:F,"Success") -> 15 | Q14: A116 | R14: =IF(COUNTIFS(C:C,Q14,F:F,"Success")>0,1,0) -> 1
A15: T0014 | B15: 46278 | C15: A121 | D15: P01 | E15: 1000 | F15: Success | G15: Distributor | H15: East | I15: =TEXT(B15,"yyyy-mm") -> 2026-09 | J15: =IFERROR(_xludf.XLOOKUP(C15,'Agent Master'!$A:$A,'Agent Master'!$B:$B,"Missing"),"Missing") -> Missing | K15: =IFERROR(_xludf.XLOOKUP(C15,'Agent Master'!$A:$A,'Agent Master'!$C:$C,"Missing"),"Missing") -> Missing | L15: =TEXT(B15,"mmmm") -> September | M15: =_xlfn.XLOOKUP('Transaction Data'!D15,ProductMap[Product Code],ProductMap[Product Name]) -> AEPS | N15: =TEXT(B15,"yyyy-mm") -> 2026-09 | O15: {=IFERROR(_xlfn.XLOOKUP(C15,AgentMaster[[#All],[Agent ID]],AgentMaster[[#All],[Agent Name]]),"")} -> Agent 121 | P15: =COUNTIFS(O:O,O15,F:F,"Success") -> 7 | Q15: A121 | R15: =IF(COUNTIFS(C:C,Q15,F:F,"Success")>0,1,0) -> 1
A16: T0015 | B16: 46252 | C16: A105 | D16: P02 | E16: 10000 | F16: Success | G16: Retailer | H16: East | I16: =TEXT(B16,"yyyy-mm") -> 2026-08 | J16: =IFERROR(_xludf.XLOOKUP(C16,'Agent Master'!$A:$A,'Agent Master'!$B:$B,"Missing"),"Missing") -> Missing | K16: =IFERROR(_xludf.XLOOKUP(C16,'Agent Master'!$A:$A,'Agent Master'!$C:$C,"Missing"),"Missing") -> Missing | L16: =TEXT(B16,"mmmm") -> August | M16: =_xlfn.XLOOKUP('Transaction Data'!D16,ProductMap[Product Code],ProductMap[Product Name]) -> UPI | N16: =TEXT(B16,"yyyy-mm") -> 2026-08 | O16: {=IFERROR(_xlfn.XLOOKUP(C16,AgentMaster[[#All],[Agent ID]],AgentMaster[[#All],[Agent Name]]),"")} -> Agent 105 | P16: =COUNTIFS(O:O,O16,F:F,"Success") -> 8 | Q16: A105 | R16: =IF(COUNTIFS(C:C,Q16,F:F,"Success")>0,1,0) -> 1
A17: T0016 | B17: 46260 | D17: P04 | E17: 750 | F17: Success | G17: Retailer | H17: West | I17: =TEXT(B17,"yyyy-mm") -> 2026-08 | J17: =IFERROR(_xludf.XLOOKUP(C17,'Agent Master'!$A:$A,'Agent Master'!$B:$B,"Missing"),"Missing") -> Missing | K17: =IFERROR(_xludf.XLOOKUP(C17,'Agent Master'!$A:$A,'Agent Master'!$C:$C,"Missing"),"Missing") -> Missing | L17: =TEXT(B17,"mmmm") -> August | M17: =_xlfn.XLOOKUP('Transaction Data'!D17,ProductMap[Product Code],ProductMap[Product Name]) -> DMT | N17: =TEXT(B17,"yyyy-mm") -> 2026-08 | O17: {=IFERROR(_xlfn.XLOOKUP(C17,AgentMaster[[#All],[Agent ID]],AgentMaster[[#All],[Agent Name]]),"")} | P17: =COUNTIFS(O:O,O17,F:F,"Success") -> 25 | Q17: 0 | R17: =IF(COUNTIFS(C:C,Q17,F:F,"Success")>0,1,0) -> 0
A18: T0017 | B18: 46282 | C18: A136 | D18: P05 | E18: 1500 | F18: Failed | G18: Distributor | H18: East | I18: =TEXT(B18,"yyyy-mm") -> 2026-09 | J18: =IFERROR(_xludf.XLOOKUP(C18,'Agent Master'!$A:$A,'Agent Master'!$B:$B,"Missing"),"Missing") -> Missing | K18: =IFERROR(_xludf.XLOOKUP(C18,'Agent Master'!$A:$A,'Agent Master'!$C:$C,"Missing"),"Missing") -> Missing | L18: =TEXT(B18,"mmmm") -> September | M18: =_xlfn.XLOOKUP('Transaction Data'!D18,ProductMap[Product Code],ProductMap[Product Name]) -> BBPS | N18: =TEXT(B18,"yyyy-mm") -> 2026-09 | O18: {=IFERROR(_xlfn.XLOOKUP(C18,AgentMaster[[#All],[Agent ID]],AgentMaster[[#All],[Agent Name]]),"")} -> Agent 136 | P18: =COUNTIFS(O:O,O18,F:F,"Success") -> 16 | Q18: A136 | R18: =IF(COUNTIFS(C:C,Q18,F:F,"Success")>0,1,0) -> 1
A19: T0018 | B19: 46258 | C19: A115 | D19: P02 | E19: 7500 | F19: Success | G19: Retailer | H19: North | I19: =TEXT(B19,"yyyy-mm") -> 2026-08 | J19: =IFERROR(_xludf.XLOOKUP(C19,'Agent Master'!$A:$A,'Agent Master'!$B:$B,"Missing"),"Missing") -> Missing | K19: =IFERROR(_xludf.XLOOKUP(C19,'Agent Master'!$A:$A,'Agent Master'!$C:$C,"Missing"),"Missing") -> Missing | L19: =TEXT(B19,"mmmm") -> August | M19: =_xlfn.XLOOKUP('Transaction Data'!D19,ProductMap[Product Code],ProductMap[Product Name]) -> UPI | N19: =TEXT(B19,"yyyy-mm") -> 2026-08 | O19: {=IFERROR(_xlfn.XLOOKUP(C19,AgentMaster[[#All],[Agent ID]],AgentMaster[[#All],[Agent Name]]),"")} -> Agent 115 | P19: =COUNTIFS(O:O,O19,F:F,"Success") -> 11 | Q19: A101 | R19: =IF(COUNTIFS(C:C,Q19,F:F,"Success")>0,1,0) -> 1
A20: T0019 | B20: 46290 | C20: A108 | D20: P02 | E20: 12500 | F20: Success | G20: Retailer | H20: East | I20: =TEXT(B20,"yyyy-mm") -> 2026-09 | J20: =IFERROR(_xludf.XLOOKUP(C20,'Agent Master'!$A:$A,'Agent Master'!$B:$B,"Missing"),"Missing") -> Missing | K20: =IFERROR(_xludf.XLOOKUP(C20,'Agent Master'!$A:$A,'Agent Master'!$C:$C,"Missing"),"Missing") -> Missing | L20: =TEXT(B20,"mmmm") -> September | M20: =_xlfn.XLOOKUP('Transaction Data'!D20,ProductMap[Product Code],ProductMap[Product Name]) -> UPI | N20: =TEXT(B20,"yyyy-mm") -> 2026-09 | O20: {=IFERROR(_xlfn.XLOOKUP(C20,AgentMaster[[#All],[Agent ID]],AgentMaster[[#All],[Agent Name]]),"")} -> Agent 108 | P20: =COUNTIFS(O:O,O20,F:F,"Success") -> 12 | Q20: A124 | R20: =IF(COUNTIFS(C:C,Q20,F:F,"Success")>0,1,0) -> 1
A21: T0020 | B21: 46273 | C21: A105 | D21: P04 | E21: 2500 | F21: Failed | G21: Distributor | H21: South | I21: =TEXT(B21,"yyyy-mm") -> 2026-09 | J21: =IFERROR(_xludf.XLOOKUP(C21,'Agent Master'!$A:$A,'Agent Master'!$B:$B,"Missing"),"Missing") -> Missing | K21: =IFERROR(_xludf.XLOOKUP(C21,'Agent Master'!$A:$A,'Agent Master'!$C:$C,"Missing"),"Missing") -> Missing | L21: =TEXT(B21,"mmmm") -> September | M21: =_xlfn.XLOOKUP('Transaction Data'!D21,ProductMap[Product Code],ProductMap[Product Name]) -> DMT | N21: =TEXT(B21,"yyyy-mm") -> 2026-09 | O21: {=IFERROR(_xlfn.XLOOKUP(C21,AgentMaster[[#All],[Agent ID]],AgentMaster[[#All],[Agent Name]]),"")} -> Agent 105 | P21: =COUNTIFS(O:O,O21,F:F,"Success") -> 8 | Q21: A137 | R21: =IF(COUNTIFS(C:C,Q21,F:F,"Success")>0,1,0) -> 1
A22: T0021 | B22: 46270 | C22: A101 | D22: P06 | E22: 15000 | F22: Success | G22: Retailer | H22: South | I22: =TEXT(B22,"yyyy-mm") -> 2026-09 | J22: =IFERROR(_xludf.XLOOKUP(C22,'Agent Master'!$A:$A,'Agent Master'!$B:$B,"Missing"),"Missing") -> Missing | K22: =IFERROR(_xludf.XLOOKUP(C22,'Agent Master'!$A:$A,'Agent Master'!$C:$C,"Missing"),"Missing") -> Missing | L22: =TEXT(B22,"mmmm") -> September | M22: =_xlfn.XLOOKUP('Transaction Data'!D22,ProductMap[Product Code],ProductMap[Product Name]) -> MATM | N22: =TEXT(B22,"yyyy-mm") -> 2026-09 | O22: {=IFERROR(_xlfn.XLOOKUP(C22,AgentMaster[[#All],[Agent ID]],AgentMaster[[#All],[Agent Name]]),"")} -> Agent 101 | P22: =COUNTIFS(O:O,O22,F:F,"Success") -> 6 | Q22: A131 | R22: =IF(COUNTIFS(C:C,Q22,F:F,"Success")>0,1,0) -> 1
A23: T0022 | B23: 46284 | D23: P03 | E23: 500 | F23: Success | G23: Distributor | H23: West | I23: =TEXT(B23,"yyyy-mm") -> 2026-09 | J23: =IFERROR(_xludf.XLOOKUP(C23,'Agent Master'!$A:$A,'Agent Master'!$B:$B,"Missing"),"Missing") -> Missing | K23: =IFERROR(_xludf.XLOOKUP(C23,'Agent Master'!$A:$A,'Agent Master'!$C:$C,"Missing"),"Missing") -> Missing | L23: =TEXT(B23,"mmmm") -> September | M23: =_xlfn.XLOOKUP('Transaction Data'!D23,ProductMap[Product Code],ProductMap[Product Name]) -> APAY | N23: =TEXT(B23,"yyyy-mm") -> 2026-09 | O23: {=IFERROR(_xlfn.XLOOKUP(C23,AgentMaster[[#All],[Agent ID]],AgentMaster[[#All],[Agent Name]]),"")} | P23: =COUNTIFS(O:O,O23,F:F,"Success") -> 25 | Q23: A135 | R23: =IF(COUNTIFS(C:C,Q23,F:F,"Success")>0,1,0) -> 1
A24: T0023 | B24: 46264 | C24: A101 | D24: P06 | E24: 15000 | F24: Success | G24: Retailer | H24: West | I24: =TEXT(B24,"yyyy-mm") -> 2026-08 | J24: =IFERROR(_xludf.XLOOKUP(C24,'Agent Master'!$A:$A,'Agent Master'!$B:$B,"Missing"),"Missing") -> Missing | K24: =IFERROR(_xludf.XLOOKUP(C24,'Agent Master'!$A:$A,'Agent Master'!$C:$C,"Missing"),"Missing") -> Missing | L24: =TEXT(B24,"mmmm") -> August | M24: =_xlfn.XLOOKUP('Transaction Data'!D24,ProductMap[Product Code],ProductMap[Product Name]) -> MATM | N24: =TEXT(B24,"yyyy-mm") -> 2026-08 | O24: {=IFERROR(_xlfn.XLOOKUP(C24,AgentMaster[[#All],[Agent ID]],AgentMaster[[#All],[Agent Name]]),"")} -> Agent 101 | P24: =COUNTIFS(O:O,O24,F:F,"Success") -> 6 | Q24: A103 | R24: =IF(COUNTIFS(C:C,Q24,F:F,"Success")>0,1,0) -> 1
A25: T0024 | B25: 46267 | C25: A107 | D25: P06 | E25: 1500 | F25: Success | G25: Retailer | H25: West | I25: =TEXT(B25,"yyyy-mm") -> 2026-09 | J25: =IFERROR(_xludf.XLOOKUP(C25,'Agent Master'!$A:$A,'Agent Master'!$B:$B,"Missing"),"Missing") -> Missing | K25: =IFERROR(_xludf.XLOOKUP(C25,'Agent Master'!$A:$A,'Agent Master'!$C:$C,"Missing"),"Missing") -> Missing | L25: =TEXT(B25,"mmmm") -> September | M25: =_xlfn.XLOOKUP('Transaction Data'!D25,ProductMap[Product Code],ProductMap[Product Name]) -> MATM | N25: =TEXT(B25,"yyyy-mm") -> 2026-09 | O25: {=IFERROR(_xlfn.XLOOKUP(C25,AgentMaster[[#All],[Agent ID]],AgentMaster[[#All],[Agent Name]]),"")} -> Agent 107 | P25: =COUNTIFS(O:O,O25,F:F,"Success") -> 16 | Q25: A132 | R25: =IF(COUNTIFS(C:C,Q25,F:F,"Success")>0,1,0) -> 1
A26: T0025 | B26: 46244 | C26: A124 | D26: P02 | E26: 7500 | F26: Success | G26: Retailer | H26: South | I26: =TEXT(B26,"yyyy-mm") -> 2026-08 | J26: =IFERROR(_xludf.XLOOKUP(C26,'Agent Master'!$A:$A,'Agent Master'!$B:$B,"Missing"),"Missing") -> Missing | K26: =IFERROR(_xludf.XLOOKUP(C26,'Agent Master'!$A:$A,'Agent Master'!$C:$C,"Missing"),"Missing") -> Missing | L26: =TEXT(B26,"mmmm") -> August | M26: =_xlfn.XLOOKUP('Transaction Data'!D26,ProductMap[Product Code],ProductMap[Product Name]) -> UPI | N26: =TEXT(B26,"yyyy-mm") -> 2026-08 | O26: {=IFERROR(_xlfn.XLOOKUP(C26,AgentMaster[[#All],[Agent ID]],AgentMaster[[#All],[Agent Name]]),"")} -> Agent 124 | P26: =COUNTIFS(O:O,O26,F:F,"Success") -> 11 | Q26: A128 | R26: =IF(COUNTIFS(C:C,Q26,F:F,"Success")>0,1,0) -> 1
A27: T0026 | B27: 46266 | C27: A102 | D27: P01 | E27: 2000 | F27: Success | G27: Retailer | H27: North | I27: =TEXT(B27,"yyyy-mm") -> 2026-09 | J27: =IFERROR(_xludf.XLOOKUP(C27,'Agent Master'!$A:$A,'Agent Master'!$B:$B,"Missing"),"Missing") -> Missing | K27: =IFERROR(_xludf.XLOOKUP(C27,'Agent Master'!$A:$A,'Agent Master'!$C:$C,"Missing"),"Missing") -> Missing | L27: =TEXT(B27,"mmmm") -> September | M27: =_xlfn.XLOOKUP('Transaction Data'!D27,ProductMap[Product Code],ProductMap[Product Name]) -> AEPS | N27: =TEXT(B27,"yyyy-mm") -> 2026-09 | O27: {=IFERROR(_xlfn.XLOOKUP(C27,AgentMaster[[#All],[Agent ID]],AgentMaster[[#All],[Agent Name]]),"")} -> Agent 102 | P27: =COUNTIFS(O:O,O27,F:F,"Success") -> 13 | Q27: A126 | R27: =IF(COUNTIFS(C:C,Q27,F:F,"Success")>0,1,0) -> 1
A28: T0027 | B28: 46250 | C28: A137 | D28: P01 | E28: 500 | F28: Success | G28: Retailer | H28: West | I28: =TEXT(B28,"yyyy-mm") -> 2026-08 | J28: =IFERROR(_xludf.XLOOKUP(C28,'Agent Master'!$A:$A,'Agent Master'!$B:$B,"Missing"),"Missing") -> Missing | K28: =IFERROR(_xludf.XLOOKUP(C28,'Agent Master'!$A:$A,'Agent Master'!$C:$C,"Missing"),"Missing") -> Missing | L28: =TEXT(B28,"mmmm") -> August | M28: =_xlfn.XLOOKUP('Transaction Data'!D28,ProductMap[Product Code],ProductMap[Product Name]) -> AEPS | N28: =TEXT(B28,"yyyy-mm") -> 2026-08 | O28: {=IFERROR(_xlfn.XLOOKUP(C28,AgentMaster[[#All],[Agent ID]],AgentMaster[[#All],[Agent Name]]),"")} -> Agent 137 | P28: =COUNTIFS(O:O,O28,F:F,"Success") -> 11 | Q28: A125 | R28: =IF(COUNTIFS(C:C,Q28,F:F,"Success")>0,1,0) -> 1
A29: T0028 | B29: 46243 | C29: A131 | D29: P05 | E29: 750 | F29: Success | G29: Retailer | H29: East | I29: =TEXT(B29,"yyyy-mm") -> 2026-08 | J29: =IFERROR(_xludf.XLOOKUP(C29,'Agent Master'!$A:$A,'Agent Master'!$B:$B,"Missing"),"Missing") -> Missing | K29: =IFERROR(_xludf.XLOOKUP(C29,'Agent Master'!$A:$A,'Agent Master'!$C:$C,"Missing"),"Missing") -> Missing | L29: =TEXT(B29,"mmmm") -> August | M29: =_xlfn.XLOOKUP('Transaction Data'!D29,ProductMap[Product Code],ProductMap[Product Name]) -> BBPS | N29: =TEXT(B29,"yyyy-mm") -> 2026-08 | O29: {=IFERROR(_xlfn.XLOOKUP(C29,AgentMaster[[#All],[Agent ID]],AgentMaster[[#All],[Agent Name]]),"")} -> Agent 131 | P29: =COUNTIFS(O:O,O29,F:F,"Success") -> 11 | Q29: A114 | R29: =IF(COUNTIFS(C:C,Q29,F:F,"Success")>0,1,0) -> 1
A30: T0029 | B30: 46248 | C30: A135 | D30: P06 | E30: 15000 | F30: Success | G30: Retailer | H30: South | I30: =TEXT(B30,"yyyy-mm") -> 2026-08 | J30: =IFERROR(_xludf.XLOOKUP(C30,'Agent Master'!$A:$A,'Agent Master'!$B:$B,"Missing"),"Missing") -> Missing | K30: =IFERROR(_xludf.XLOOKUP(C30,'Agent Master'!$A:$A,'Agent Master'!$C:$C,"Missing"),"Missing") -> Missing | L30: =TEXT(B30,"mmmm") -> August | M30: =_xlfn.XLOOKUP('Transaction Data'!D30,ProductMap[Product Code],ProductMap[Product Name]) -> MATM | N30: =TEXT(B30,"yyyy-mm") -> 2026-08 | O30: {=IFERROR(_xlfn.XLOOKUP(C30,AgentMaster[[#All],[Agent ID]],AgentMaster[[#All],[Agent Name]]),"")} -> Agent 135 | P30: =COUNTIFS(O:O,O30,F:F,"Success") -> 19 | Q30: A104 | R30: =IF(COUNTIFS(C:C,Q30,F:F,"Success")>0,1,0) -> 1
A31: T0030 | B31: 46260 | D31: P03 | E31: 5000 | F31: Success | G31: Distributor | H31: North | I31: =TEXT(B31,"yyyy-mm") -> 2026-08 | J31: =IFERROR(_xludf.XLOOKUP(C31,'Agent Master'!$A:$A,'Agent Master'!$B:$B,"Missing"),"Missing") -> Missing | K31: =IFERROR(_xludf.XLOOKUP(C31,'Agent Master'!$A:$A,'Agent Master'!$C:$C,"Missing"),"Missing") -> Missing | L31: =TEXT(B31,"mmmm") -> August | M31: =_xlfn.XLOOKUP('Transaction Data'!D31,ProductMap[Product Code],ProductMap[Product Name]) -> APAY | N31: =TEXT(B31,"yyyy-mm") -> 2026-08 | O31: {=IFERROR(_xlfn.XLOOKUP(C31,AgentMaster[[#All],[Agent ID]],AgentMaster[[#All],[Agent Name]]),"")} | P31: =COUNTIFS(O:O,O31,F:F,"Success") -> 25 | Q31: A133 | R31: =IF(COUNTIFS(C:C,Q31,F:F,"Success")>0,1,0) -> 1
A32: T0031 | B32: 46250 | C32: A115 | D32: P01 | E32: 2000 | F32: Success | G32: Retailer | H32: West | I32: =TEXT(B32,"yyyy-mm") -> 2026-08 | J32: =IFERROR(_xludf.XLOOKUP(C32,'Agent Master'!$A:$A,'Agent Master'!$B:$B,"Missing"),"Missing") -> Missing | K32: =IFERROR(_xludf.XLOOKUP(C32,'Agent Master'!$A:$A,'Agent Master'!$C:$C,"Missing"),"Missing") -> Missing | L32: =TEXT(B32,"mmmm") -> August | M32: =_xlfn.XLOOKUP('Transaction Data'!D32,ProductMap[Product Code],ProductMap[Product Name]) -> AEPS | N32: =TEXT(B32,"yyyy-mm") -> 2026-08 | O32: {=IFERROR(_xlfn.XLOOKUP(C32,AgentMaster[[#All],[Agent ID]],AgentMaster[[#All],[Agent Name]]),"")} -> Agent 115 | P32: =COUNTIFS(O:O,O32,F:F,"Success") -> 11 | Q32: A106 | R32: =IF(COUNTIFS(C:C,Q32,F:F,"Success")>0,1,0) -> 1
A33: T0032 | B33: 46272 | C33: A115 | D33: P01 | E33: 500 | F33: Success | G33: Retailer | H33: North | I33: =TEXT(B33,"yyyy-mm") -> 2026-09 | J33: =IFERROR(_xludf.XLOOKUP(C33,'Agent Master'!$A:$A,'Agent Master'!$B:$B,"Missing"),"Missing") -> Missing | K33: =IFERROR(_xludf.XLOOKUP(C33,'Agent Master'!$A:$A,'Agent Master'!$C:$C,"Missing"),"Missing") -> Missing | L33: =TEXT(B33,"mmmm") -> September | M33: =_xlfn.XLOOKUP('Transaction Data'!D33,ProductMap[Product Code],ProductMap[Product Name]) -> AEPS | N33: =TEXT(B33,"yyyy-mm") -> 2026-09 | O33: {=IFERROR(_xlfn.XLOOKUP(C33,AgentMaster[[#All],[Agent ID]],AgentMaster[[#All],[Agent Name]]),"")} -> Agent 115 | P33: =COUNTIFS(O:O,O33,F:F,"Success") -> 11 | Q33: A117 | R33: =IF(COUNTIFS(C:C,Q33,F:F,"Success")>0,1,0) -> 1
A34: T0033 | B34: 46292 | C34: A103 | D34: P03 | E34: 500 | F34: Success | G34: Retailer | H34: South | I34: =TEXT(B34,"yyyy-mm") -> 2026-09 | J34: =IFERROR(_xludf.XLOOKUP(C34,'Agent Master'!$A:$A,'Agent Master'!$B:$B,"Missing"),"Missing") -> Missing | K34: =IFERROR(_xludf.XLOOKUP(C34,'Agent Master'!$A:$A,'Agent Master'!$C:$C,"Missing"),"Missing") -> Missing | L34: =TEXT(B34,"mmmm") -> September | M34: =_xlfn.XLOOKUP('Transaction Data'!D34,ProductMap[Product Code],ProductMap[Product Name]) -> APAY | N34: =TEXT(B34,"yyyy-mm") -> 2026-09 | O34: {=IFERROR(_xlfn.XLOOKUP(C34,AgentMaster[[#All],[Agent ID]],AgentMaster[[#All],[Agent Name]]),"")} -> Agent 103 | P34: =COUNTIFS(O:O,O34,F:F,"Success") -> 11 | Q34: A109 | R34: =IF(COUNTIFS(C:C,Q34,F:F,"Success")>0,1,0) -> 1
A35: T0034 | B35: 46277 | C35: A132 | D35: P02 | E35: 7500 | F35: Success | G35: Retailer | H35: East | I35: =TEXT(B35,"yyyy-mm") -> 2026-09 | J35: =IFERROR(_xludf.XLOOKUP(C35,'Agent Master'!$A:$A,'Agent Master'!$B:$B,"Missing"),"Missing") -> Missing | K35: =IFERROR(_xludf.XLOOKUP(C35,'Agent Master'!$A:$A,'Agent Master'!$C:$C,"Missing"),"Missing") -> Missing | L35: =TEXT(B35,"mmmm") -> September | M35: =_xlfn.XLOOKUP('Transaction Data'!D35,ProductMap[Product Code],ProductMap[Product Name]) -> UPI | N35: =TEXT(B35,"yyyy-mm") -> 2026-09 | O35: {=IFERROR(_xlfn.XLOOKUP(C35,AgentMaster[[#All],[Agent ID]],AgentMaster[[#All],[Agent Name]]),"")} -> Agent 132 | P35: =COUNTIFS(O:O,O35,F:F,"Success") -> 8 | Q35: A129 | R35: =IF(COUNTIFS(C:C,Q35,F:F,"Success")>0,1,0) -> 1
A36: T0035 | B36: 46250 | C36: A131 | D36: P04 | E36: 1000 | F36: Success | G36: Retailer | H36: East | I36: =TEXT(B36,"yyyy-mm") -> 2026-08 | J36: =IFERROR(_xludf.XLOOKUP(C36,'Agent Master'!$A:$A,'Agent Master'!$B:$B,"Missing"),"Missing") -> Missing | K36: =IFERROR(_xludf.XLOOKUP(C36,'Agent Master'!$A:$A,'Agent Master'!$C:$C,"Missing"),"Missing") -> Missing | L36: =TEXT(B36,"mmmm") -> August | M36: =_xlfn.XLOOKUP('Transaction Data'!D36,ProductMap[Product Code],ProductMap[Product Name]) -> DMT | N36: =TEXT(B36,"yyyy-mm") -> 2026-08 | O36: {=IFERROR(_xlfn.XLOOKUP(C36,AgentMaster[[#All],[Agent ID]],AgentMaster[[#All],[Agent Name]]),"")} -> Agent 131 | P36: =COUNTIFS(O:O,O36,F:F,"Success") -> 11 | Q36: A112 | R36: =IF(COUNTIFS(C:C,Q36,F:F,"Success")>0,1,0) -> 1
A37: T0036 | B37: 46257 | C37: A128 | D37: P04 | E37: 5000 | F37: Success | G37: Retailer | H37: North | I37: =TEXT(B37,"yyyy-mm") -> 2026-08 | J37: =IFERROR(_xludf.XLOOKUP(C37,'Agent Master'!$A:$A,'Agent Master'!$B:$B,"Missing"),"Missing") -> Missing | K37: =IFERROR(_xludf.XLOOKUP(C37,'Agent Master'!$A:$A,'Agent Master'!$C:$C,"Missing"),"Missing") -> Missing | L37: =TEXT(B37,"mmmm") -> August | M37: =_xlfn.XLOOKUP('Transaction Data'!D37,ProductMap[Product Code],ProductMap[Product Name]) -> DMT | N37: =TEXT(B37,"yyyy-mm") -> 2026-08 | O37: {=IFERROR(_xlfn.XLOOKUP(C37,AgentMaster[[#All],[Agent ID]],AgentMaster[[#All],[Agent Name]]),"")} -> Agent 128 | P37: =COUNTIFS(O:O,O37,F:F,"Success") -> 16 | Q37: A127 | R37: =IF(COUNTIFS(C:C,Q37,F:F,"Success")>0,1,0) -> 1
A38: T0037 | B38: 46238 | C38: A126 | D38: P06 | E38: 2000 | F38: Success | G38: Retailer | H38: West | I38: =TEXT(B38,"yyyy-mm") -> 2026-08 | J38: =IFERROR(_xludf.XLOOKUP(C38,'Agent Master'!$A:$A,'Agent Master'!$B:$B,"Missing"),"Missing") -> Missing | K38: =IFERROR(_xludf.XLOOKUP(C38,'Agent Master'!$A:$A,'Agent Master'!$C:$C,"Missing"),"Missing") -> Missing | L38: =TEXT(B38,"mmmm") -> August | M38: =_xlfn.XLOOKUP('Transaction Data'!D38,ProductMap[Product Code],ProductMap[Product Name]) -> MATM | N38: =TEXT(B38,"yyyy-mm") -> 2026-08 | O38: {=IFERROR(_xlfn.XLOOKUP(C38,AgentMaster[[#All],[Agent ID]],AgentMaster[[#All],[Agent Name]]),"")} -> Agent 126 | P38: =COUNTIFS(O:O,O38,F:F,"Success") -> 11 | Q38: A134 | R38: =IF(COUNTIFS(C:C,Q38,F:F,"Success")>0,1,0) -> 1
A39: T0038 | B39: 46247 | C39: A135 | D39: P04 | E39: 750 | F39: Success | G39: Retailer | H39: South | I39: =TEXT(B39,"yyyy-mm") -> 2026-08 | J39: =IFERROR(_xludf.XLOOKUP(C39,'Agent Master'!$A:$A,'Agent Master'!$B:$B,"Missing"),"Missing") -> Missing | K39: =IFERROR(_xludf.XLOOKUP(C39,'Agent Master'!$A:$A,'Agent Master'!$C:$C,"Missing"),"Missing") -> Missing | L39: =TEXT(B39,"mmmm") -> August | M39: =_xlfn.XLOOKUP('Transaction Data'!D39,ProductMap[Product Code],ProductMap[Product Name]) -> DMT | N39: =TEXT(B39,"yyyy-mm") -> 2026-08 | O39: {=IFERROR(_xlfn.XLOOKUP(C39,AgentMaster[[#All],[Agent ID]],AgentMaster[[#All],[Agent Name]]),"")} -> Agent 135 | P39: =COUNTIFS(O:O,O39,F:F,"Success") -> 19 | Q39: A122 | R39: =IF(COUNTIFS(C:C,Q39,F:F,"Success")>0,1,0) -> 1
A40: T0039 | B40: 46264 | C40: A116 | D40: P01 | E40: 5000 | F40: Success | G40: Retailer | H40: North | I40: =TEXT(B40,"yyyy-mm") -> 2026-08 | J40: =IFERROR(_xludf.XLOOKUP(C40,'Agent Master'!$A:$A,'Agent Master'!$B:$B,"Missing"),"Missing") -> Missing | K40: =IFERROR(_xludf.XLOOKUP(C40,'Agent Master'!$A:$A,'Agent Master'!$C:$C,"Missing"),"Missing") -> Missing | L40: =TEXT(B40,"mmmm") -> August | M40: =_xlfn.XLOOKUP('Transaction Data'!D40,ProductMap[Product Code],ProductMap[Product Name]) -> AEPS | N40: =TEXT(B40,"yyyy-mm") -> 2026-08 | O40: {=IFERROR(_xlfn.XLOOKUP(C40,AgentMaster[[#All],[Agent ID]],AgentMaster[[#All],[Agent Name]]),"")} -> Agent 116 | P40: =COUNTIFS(O:O,O40,F:F,"Success") -> 15 | Q40: A120 | R40: =IF(COUNTIFS(C:C,Q40,F:F,"Success")>0,1,0) -> 1
...

Sheet Agent Master
A1: Agent Master
A3: Agent ID | B3: Agent Name | C3: ASM | D3: State
A4: A101 | B4: Agent 101 | C4: ASM North 1 | D4: Delhi
A5: A102 | B5: Agent 102 | C5: ASM North 2 | D5: Haryana
A6: A103 | B6: Agent 103 | C6: ASM West 1 | D6: Maharashtra
A7: A104 | B7: Agent 104 | C7: ASM South 1 | D7: Karnataka
A8: A105 | B8: Agent 105 | C8: ASM East 1 | D8: West Bengal
A9: A106 | B9: Agent 106 | C9: ASM North 1 | D9: Delhi
A10: A107 | B10: Agent 107 | C10: ASM North 2 | D10: Haryana
A11: A108 | B11: Agent 108 | C11: ASM West 1 | D11: Maharashtra
A12: A109 | B12: Agent 109 | C12: ASM South 1 | D12: Karnataka
A13: A110 | B13: Agent 110 | C13: ASM East 1 | D13: West Bengal
A14: A111 | B14: Agent 111 | C14: ASM North 1 | D14: Delhi
... A43: A140 | B43: Agent 140 | C43: ASM East 1 | D43: West Bengal

Sheet Product Mapping
A1: Product Mapping
A3: Product Code | B3: Product Name | C3: Category
A4: P01 | B4: AEPS | C4: Banking
A5: P02 | B5: UPI | C5: Payments
A6: P03 | B6: APAY | C6: Banking
A7: P04 | B7: DMT | C7: Remittance
A8: P05 | B8: BBPS | C8: Bill Pay
A9: P06 | B9: MATM | C9: Banking
